[2025-05-20T21:20:13.846+0000] {taskinstance.py:1956} INFO - Dependencies all met for dep_context=non-requeueable deps ti=<TaskInstance: crypto_elt_pipeline.run_dbt_models manual__2025-05-20T15:46:26.526622+00:00 [queued]>
[2025-05-20T21:20:13.849+0000] {taskinstance.py:1956} INFO - Dependencies all met for dep_context=requeueable deps ti=<TaskInstance: crypto_elt_pipeline.run_dbt_models manual__2025-05-20T15:46:26.526622+00:00 [queued]>
[2025-05-20T21:20:13.850+0000] {taskinstance.py:2170} INFO - Starting attempt 2 of 2
[2025-05-20T21:20:13.854+0000] {taskinstance.py:2191} INFO - Executing <Task(BashOperator): run_dbt_models> on 2025-05-20 15:46:26.526622+00:00
[2025-05-20T21:20:13.857+0000] {standard_task_runner.py:60} INFO - Started process 181 to run task
[2025-05-20T21:20:13.862+0000] {standard_task_runner.py:87} INFO - Running: ['***', 'tasks', 'run', 'crypto_elt_pipeline', 'run_dbt_models', 'manual__2025-05-20T15:46:26.526622+00:00', '--job-id', '28', '--raw', '--subdir', 'DAGS_FOLDER/elt_dag.py', '--cfg-path', '/tmp/tmplmye2af1']
[2025-05-20T21:20:13.865+0000] {standard_task_runner.py:88} INFO - Job 28: Subtask run_dbt_models
[2025-05-20T21:20:13.874+0000] {logging_mixin.py:188} WARNING - /home/***/.local/lib/python3.9/site-packages/***/settings.py:194 DeprecationWarning: The sql_alchemy_conn option in [core] has been moved to the sql_alchemy_conn option in [database] - the old setting has been used, but please update your config.
[2025-05-20T21:20:13.890+0000] {task_command.py:423} INFO - Running <TaskInstance: crypto_elt_pipeline.run_dbt_models manual__2025-05-20T15:46:26.526622+00:00 [running]> on host 7224395b244e
[2025-05-20T21:20:13.930+0000] {taskinstance.py:2480} INFO - Exporting env vars: AIRFLOW_CTX_DAG_OWNER='deepak' AIRFLOW_CTX_DAG_ID='crypto_elt_pipeline' AIRFLOW_CTX_TASK_ID='run_dbt_models' AIRFLOW_CTX_EXECUTION_DATE='2025-05-20T15:46:26.526622+00:00' AIRFLOW_CTX_TRY_NUMBER='2' AIRFLOW_CTX_DAG_RUN_ID='manual__2025-05-20T15:46:26.526622+00:00'
[2025-05-20T21:20:13.931+0000] {subprocess.py:63} INFO - Tmp dir root location: /tmp
[2025-05-20T21:20:13.931+0000] {subprocess.py:75} INFO - Running command: ['/usr/bin/bash', '-c', 'cd /opt/***/dbt_project && dbt run']
[2025-05-20T21:20:13.938+0000] {subprocess.py:86} INFO - Output:
[2025-05-20T21:20:13.943+0000] {subprocess.py:93} INFO - /usr/bin/bash: line 1: dbt: command not found
[2025-05-20T21:20:13.943+0000] {subprocess.py:97} INFO - Command exited with return code 127
[2025-05-20T21:20:13.948+0000] {taskinstance.py:2698} ERROR - Task failed with exception
Traceback (most recent call last):
  File "/home/airflow/.local/lib/python3.9/site-packages/airflow/models/taskinstance.py", line 433, in _execute_task
    result = execute_callable(context=context, **execute_callable_kwargs)
  File "/home/airflow/.local/lib/python3.9/site-packages/airflow/operators/bash.py", line 212, in execute
    raise AirflowException(
airflow.exceptions.AirflowException: Bash command failed. The command returned a non-zero exit code 127.
[2025-05-20T21:20:13.950+0000] {taskinstance.py:1138} INFO - Marking task as FAILED. dag_id=crypto_elt_pipeline, task_id=run_dbt_models, execution_date=20250520T154626, start_date=20250520T212013, end_date=20250520T212013
[2025-05-20T21:20:13.957+0000] {standard_task_runner.py:107} ERROR - Failed to execute job 28 for task run_dbt_models (Bash command failed. The command returned a non-zero exit code 127.; 181)
[2025-05-20T21:20:13.963+0000] {local_task_job_runner.py:234} INFO - Task exited with return code 1
[2025-05-20T21:20:13.971+0000] {taskinstance.py:3280} INFO - 0 downstream tasks scheduled from follow-on schedule check
