[2025-05-20T21:47:29.176+0000] {taskinstance.py:1956} INFO - Dependencies all met for dep_context=non-requeueable deps ti=<TaskInstance: crypto_elt_pipeline.run_dbt_models scheduled__2025-05-19T00:00:00+00:00 [queued]>
[2025-05-20T21:47:29.181+0000] {taskinstance.py:1956} INFO - Dependencies all met for dep_context=requeueable deps ti=<TaskInstance: crypto_elt_pipeline.run_dbt_models scheduled__2025-05-19T00:00:00+00:00 [queued]>
[2025-05-20T21:47:29.181+0000] {taskinstance.py:2170} INFO - Starting attempt 1 of 2
[2025-05-20T21:47:29.189+0000] {taskinstance.py:2191} INFO - Executing <Task(BashOperator): run_dbt_models> on 2025-05-19 00:00:00+00:00
[2025-05-20T21:47:29.202+0000] {standard_task_runner.py:60} INFO - Started process 398 to run task
[2025-05-20T21:47:29.209+0000] {standard_task_runner.py:87} INFO - Running: ['***', 'tasks', 'run', 'crypto_elt_pipeline', 'run_dbt_models', 'scheduled__2025-05-19T00:00:00+00:00', '--job-id', '4', '--raw', '--subdir', 'DAGS_FOLDER/elt_dag.py', '--cfg-path', '/tmp/tmp80hjtwtw']
[2025-05-20T21:47:29.211+0000] {standard_task_runner.py:88} INFO - Job 4: Subtask run_dbt_models
[2025-05-20T21:47:29.238+0000] {logging_mixin.py:188} WARNING - /home/***/.local/lib/python3.9/site-packages/***/settings.py:194 DeprecationWarning: The sql_alchemy_conn option in [core] has been moved to the sql_alchemy_conn option in [database] - the old setting has been used, but please update your config.
[2025-05-20T21:47:29.316+0000] {task_command.py:423} INFO - Running <TaskInstance: crypto_elt_pipeline.run_dbt_models scheduled__2025-05-19T00:00:00+00:00 [running]> on host eb07b9207670
[2025-05-20T21:47:29.398+0000] {taskinstance.py:2480} INFO - Exporting env vars: AIRFLOW_CTX_DAG_OWNER='deepak' AIRFLOW_CTX_DAG_ID='crypto_elt_pipeline' AIRFLOW_CTX_TASK_ID='run_dbt_models' AIRFLOW_CTX_EXECUTION_DATE='2025-05-19T00:00:00+00:00' AIRFLOW_CTX_TRY_NUMBER='1' AIRFLOW_CTX_DAG_RUN_ID='scheduled__2025-05-19T00:00:00+00:00'
[2025-05-20T21:47:29.403+0000] {subprocess.py:63} INFO - Tmp dir root location: /tmp
[2025-05-20T21:47:29.412+0000] {subprocess.py:75} INFO - Running command: ['/usr/bin/bash', '-c', 'cd /opt/***/dbt_project && dbt run']
[2025-05-20T21:47:29.430+0000] {subprocess.py:86} INFO - Output:
[2025-05-20T21:47:32.185+0000] {subprocess.py:93} INFO - Usage: dbt run [OPTIONS]
[2025-05-20T21:47:32.189+0000] {subprocess.py:93} INFO - Try 'dbt run -h' for help.
[2025-05-20T21:47:32.189+0000] {subprocess.py:93} INFO - 
[2025-05-20T21:47:32.189+0000] {subprocess.py:93} INFO - Error: Invalid value for '--profiles-dir': Path '/home/***/.dbt' does not exist.
[2025-05-20T21:47:32.352+0000] {subprocess.py:97} INFO - Command exited with return code 2
[2025-05-20T21:47:32.393+0000] {taskinstance.py:2698} ERROR - Task failed with exception
Traceback (most recent call last):
  File "/home/airflow/.local/lib/python3.9/site-packages/airflow/models/taskinstance.py", line 433, in _execute_task
    result = execute_callable(context=context, **execute_callable_kwargs)
  File "/home/airflow/.local/lib/python3.9/site-packages/airflow/operators/bash.py", line 212, in execute
    raise AirflowException(
airflow.exceptions.AirflowException: Bash command failed. The command returned a non-zero exit code 2.
[2025-05-20T21:47:32.401+0000] {taskinstance.py:1138} INFO - Marking task as UP_FOR_RETRY. dag_id=crypto_elt_pipeline, task_id=run_dbt_models, execution_date=20250519T000000, start_date=20250520T214729, end_date=20250520T214732
[2025-05-20T21:47:32.428+0000] {standard_task_runner.py:107} ERROR - Failed to execute job 4 for task run_dbt_models (Bash command failed. The command returned a non-zero exit code 2.; 398)
[2025-05-20T21:47:32.451+0000] {local_task_job_runner.py:234} INFO - Task exited with return code 1
[2025-05-20T21:47:32.511+0000] {taskinstance.py:3280} INFO - 0 downstream tasks scheduled from follow-on schedule check
