[2025-05-20T21:26:11.920+0000] {taskinstance.py:1956} INFO - Dependencies all met for dep_context=non-requeueable deps ti=<TaskInstance: crypto_elt_pipeline.run_dbt_models manual__2025-05-20T21:20:53.352599+00:00 [queued]>
[2025-05-20T21:26:11.923+0000] {taskinstance.py:1956} INFO - Dependencies all met for dep_context=requeueable deps ti=<TaskInstance: crypto_elt_pipeline.run_dbt_models manual__2025-05-20T21:20:53.352599+00:00 [queued]>
[2025-05-20T21:26:11.923+0000] {taskinstance.py:2170} INFO - Starting attempt 1 of 2
[2025-05-20T21:26:11.928+0000] {taskinstance.py:2191} INFO - Executing <Task(BashOperator): run_dbt_models> on 2025-05-20 21:20:53.352599+00:00
[2025-05-20T21:26:11.933+0000] {standard_task_runner.py:60} INFO - Started process 192 to run task
[2025-05-20T21:26:11.935+0000] {standard_task_runner.py:87} INFO - Running: ['***', 'tasks', 'run', 'crypto_elt_pipeline', 'run_dbt_models', 'manual__2025-05-20T21:20:53.352599+00:00', '--job-id', '34', '--raw', '--subdir', 'DAGS_FOLDER/elt_dag.py', '--cfg-path', '/tmp/tmpo2g8vqq5']
[2025-05-20T21:26:11.936+0000] {standard_task_runner.py:88} INFO - Job 34: Subtask run_dbt_models
[2025-05-20T21:26:11.942+0000] {logging_mixin.py:188} WARNING - /home/***/.local/lib/python3.9/site-packages/***/settings.py:194 DeprecationWarning: The sql_alchemy_conn option in [core] has been moved to the sql_alchemy_conn option in [database] - the old setting has been used, but please update your config.
[2025-05-20T21:26:11.955+0000] {task_command.py:423} INFO - Running <TaskInstance: crypto_elt_pipeline.run_dbt_models manual__2025-05-20T21:20:53.352599+00:00 [running]> on host dfe7f3e3aab8
[2025-05-20T21:26:11.991+0000] {taskinstance.py:2480} INFO - Exporting env vars: AIRFLOW_CTX_DAG_OWNER='deepak' AIRFLOW_CTX_DAG_ID='crypto_elt_pipeline' AIRFLOW_CTX_TASK_ID='run_dbt_models' AIRFLOW_CTX_EXECUTION_DATE='2025-05-20T21:20:53.352599+00:00' AIRFLOW_CTX_TRY_NUMBER='1' AIRFLOW_CTX_DAG_RUN_ID='manual__2025-05-20T21:20:53.352599+00:00'
[2025-05-20T21:26:11.992+0000] {subprocess.py:63} INFO - Tmp dir root location: /tmp
[2025-05-20T21:26:11.992+0000] {subprocess.py:75} INFO - Running command: ['/usr/bin/bash', '-c', 'cd /opt/***/dbt_project && dbt run']
[2025-05-20T21:26:12.000+0000] {subprocess.py:86} INFO - Output:
[2025-05-20T21:26:12.007+0000] {subprocess.py:93} INFO - /usr/bin/bash: line 1: dbt: command not found
[2025-05-20T21:26:12.008+0000] {subprocess.py:97} INFO - Command exited with return code 127
[2025-05-20T21:26:12.012+0000] {taskinstance.py:2698} ERROR - Task failed with exception
Traceback (most recent call last):
  File "/home/airflow/.local/lib/python3.9/site-packages/airflow/models/taskinstance.py", line 433, in _execute_task
    result = execute_callable(context=context, **execute_callable_kwargs)
  File "/home/airflow/.local/lib/python3.9/site-packages/airflow/operators/bash.py", line 212, in execute
    raise AirflowException(
airflow.exceptions.AirflowException: Bash command failed. The command returned a non-zero exit code 127.
[2025-05-20T21:26:12.014+0000] {taskinstance.py:1138} INFO - Marking task as UP_FOR_RETRY. dag_id=crypto_elt_pipeline, task_id=run_dbt_models, execution_date=20250520T212053, start_date=20250520T212611, end_date=20250520T212612
[2025-05-20T21:26:12.019+0000] {standard_task_runner.py:107} ERROR - Failed to execute job 34 for task run_dbt_models (Bash command failed. The command returned a non-zero exit code 127.; 192)
[2025-05-20T21:26:12.036+0000] {local_task_job_runner.py:234} INFO - Task exited with return code 1
[2025-05-20T21:26:12.042+0000] {taskinstance.py:3280} INFO - 0 downstream tasks scheduled from follow-on schedule check
